<?xml version="1.0" ?>
<!-- =================================================================================== -->
<!-- |    This document was autogenerated by xacro from strirus.xacro                  | -->
<!-- |    EDITING THIS FILE BY HAND IS NOT RECOMMENDED                                 | -->
<!-- =================================================================================== -->
<robot name="Strirus" xmlns:xacro="http://www.ros.org/wiki/xacro">
  <!-- plugins -->
  <!--   <gazebo>
    <plugin name="gazebo_ros_control" filename="libgazebo_ros_control.so" >
      <robotNamespace>/strirus</robotNamespace>
    </plugin>
  </gazebo>
-->
  <gazebo>
    <plugin filename="libgazebo_ros_diff_drive.so" name="differential_drive_controller">
      <alwaysOn>true</alwaysOn>
      <updateRate>30</updateRate>
      <leftJoint>leg_left_0_revolute_joint</leftJoint>
      <rightJoint>leg_right_0_revolute_joint</rightJoint>
      <wheelSeparation>2.5</wheelSeparation>
      <wheelDiameter>0.4</wheelDiameter>
      <legacyMode>false</legacyMode>
      <torque>40</torque>
      <commandTopic>cmd_vel</commandTopic>
      <odometryTopic>odom</odometryTopic>
      <odometryFrame>odom</odometryFrame>
      <robotBaseFrame>base_link</robotBaseFrame>
    </plugin>
  </gazebo>
  <!-- Import Rviz colors -->
  <material name="black">
    <color rgba="0.0 0.0 0.0 1.0"/>
  </material>
  <material name="blue">
    <color rgba="0.0 0.0 0.8 1.0"/>
  </material>
  <material name="green">
    <color rgba="0.0 0.8 0.0 1.0"/>
  </material>
  <material name="grey">
    <color rgba="0.2 0.2 0.2 1.0"/>
  </material>
  <material name="orange">
    <color rgba="1.0 0.423529411765 0.0392156862745 1.0"/>
  </material>
  <material name="brown">
    <color rgba="0.870588235294 0.811764705882 0.764705882353 1.0"/>
  </material>
  <material name="red">
    <color rgba="0.8 0.0 0.0 1.0"/>
  </material>
  <material name="white">
    <color rgba="1.0 1.0 1.0 1.0"/>
  </material>
  <!-- Body description -->
  <link name="base_link"/>
  <joint name="base_link_body_fixed" type="fixed">
    <parent link="base_link"/>
    <child link="body"/>
  </joint>
  <!-- /////////////// -->
  <link name="body">
    <inertial>
      <!-- 250 value is mass density, the value is just empiric-->
      <mass value="0.0924358891325"/>
      <origin rpy="0  0  0" xyz="0 0.528205080757  0.5"/>
      <!-- 			<inertia 
				ixx="${1/12 * body_weight * (body_height * body_height + body_length * body_length)}"  ixy="0"  ixz="0" 
				iyy="${1/12 * body_weight * (body_height * body_height + body_width * body_width)}" iyz="0" 
				izz="${1/12 * body_weight * (body_length * body_length + body_width * body_width)}" /> -->
      <inertia ixx="0.000" ixy="0" ixz="0" iyy="0.000" iyz="0" izz="0.000"/>
    </inertial>
    <collision>
      <origin rpy="0  0  0" xyz="0 0.528205080757  0.5"/>
      <geometry>
        <box size="1.25 1.05641016151 0.175"/>
      </geometry>
    </collision>
    <visual>
      <origin rpy="0  0  0" xyz="0 0.528205080757  0.5"/>
      <geometry>
        <box size="1.25 1.05641016151 0.175"/>
      </geometry>
      <material name="green"/>
    </visual>
  </link>
  <link name="leg_left_1">
    <inertial>
      <mass value="0.05"/>
      <origin rpy="0  0  0" xyz="0 0 0"/>
      <inertia ixx="0.000" ixy="0" ixz="0" iyy="0.000" iyz="0" izz="0.000"/>
    </inertial>
    <collision>
      <origin rpy="1.0471975512 0 0" xyz="0 0 0"/>
      <geometry>
        <mesh filename="package://strirus_robot_description/meshes/stl/leg_30_degree_normal.stl" scale="1.0 1.0 1.0"/>
      </geometry>
      <gazebo>
        <surface>
          <friction>
            <ode>
              <mu>0.2000</mu>
              <mu2>0.2000</mu2>
              <fdir1>0.000000 0.000000 0.000000</fdir1>
              <slip1>0.000000</slip1>
              <slip2>0.000000</slip2>
            </ode>
          </friction>
          <bounce>
            <restitution_coefficient>0.000000</restitution_coefficient>
            <threshold>100000.000000</threshold>
          </bounce>
          <contact>
            <ode>
              <soft_cfm>0.000000</soft_cfm>
              <soft_erp>0.200000</soft_erp>
              <kp>100000.000000</kp>
              <kd>1.000000</kd>
              <max_vel>100.000000</max_vel>
              <min_depth>0.001000</min_depth>
            </ode>
          </contact>
        </surface>
      </gazebo>
    </collision>
    <visual>
      <origin rpy="1.0471975512 0 0" xyz="0 0 0"/>
      <geometry>
        <mesh filename="package://strirus_robot_description/meshes/stl/leg_30_degree_normal.stl" scale="1.0 1.0 1.0"/>
      </geometry>
      <material name="blue"/>
    </visual>
  </link>
  <!-- /////////////// -->
  <joint name="leg_left_1_revolute_joint" type="revolute">
    <parent link="body"/>
    <child link="leg_left_1"/>
    <origin rpy="0       0      0" xyz="0.25 0.806410161514  0.5"/>
    <axis xyz="1 0  0"/>
    <limit effort="30" lower="-1e+100" upper="1e+100" velocity="10"/>
    <joint_properties damping="0.0" friction="0.0"/>
  </joint>
  <!-- /////////////// -->
  <transmission name="leg_left_1_transmission">
    <type>transmission_interface/SimpleTransmission</type>
    <joint name="leg_left_1_revolute_joint">
      <hardwareInterface>VelocityJointInterface</hardwareInterface>
    </joint>
    <actuator name="leg_left_0_actuator">
      <hardwareInterface>VelocityJointInterface</hardwareInterface>
      <mechanicalReduction>1</mechanicalReduction>
    </actuator>
  </transmission>
  <link name="leg_left_0">
    <inertial>
      <mass value="0.05"/>
      <origin rpy="0  0  0" xyz="0 0 0"/>
      <inertia ixx="0.000" ixy="0" ixz="0" iyy="0.000" iyz="0" izz="0.000"/>
    </inertial>
    <collision>
      <origin rpy="0.0 0 0" xyz="0 0 0"/>
      <geometry>
        <mesh filename="package://strirus_robot_description/meshes/stl/leg_30_degree_normal.stl" scale="1.0 1.0 1.0"/>
      </geometry>
      <gazebo>
        <surface>
          <friction>
            <ode>
              <mu>0.2000</mu>
              <mu2>0.2000</mu2>
              <fdir1>0.000000 0.000000 0.000000</fdir1>
              <slip1>0.000000</slip1>
              <slip2>0.000000</slip2>
            </ode>
          </friction>
          <bounce>
            <restitution_coefficient>0.000000</restitution_coefficient>
            <threshold>100000.000000</threshold>
          </bounce>
          <contact>
            <ode>
              <soft_cfm>0.000000</soft_cfm>
              <soft_erp>0.200000</soft_erp>
              <kp>100000.000000</kp>
              <kd>1.000000</kd>
              <max_vel>100.000000</max_vel>
              <min_depth>0.001000</min_depth>
            </ode>
          </contact>
        </surface>
      </gazebo>
    </collision>
    <visual>
      <origin rpy="0.0 0 0" xyz="0 0 0"/>
      <geometry>
        <mesh filename="package://strirus_robot_description/meshes/stl/leg_30_degree_normal.stl" scale="1.0 1.0 1.0"/>
      </geometry>
      <material name="blue"/>
    </visual>
  </link>
  <!-- /////////////// -->
  <joint name="leg_left_0_revolute_joint" type="revolute">
    <parent link="body"/>
    <child link="leg_left_0"/>
    <origin rpy="0       0      0" xyz="0.25 0.25  0.5"/>
    <axis xyz="1 0  0"/>
    <limit effort="30" lower="-1e+100" upper="1e+100" velocity="10"/>
    <joint_properties damping="0.0" friction="0.0"/>
  </joint>
  <!-- /////////////// -->
  <transmission name="leg_left_0_transmission">
    <type>transmission_interface/SimpleTransmission</type>
    <joint name="leg_left_0_revolute_joint">
      <hardwareInterface>VelocityJointInterface</hardwareInterface>
    </joint>
    <actuator name="leg_left_0_actuator">
      <hardwareInterface>VelocityJointInterface</hardwareInterface>
      <mechanicalReduction>1</mechanicalReduction>
    </actuator>
  </transmission>
  <link name="leg_right_1">
    <inertial>
      <mass value="0.05"/>
      <origin rpy="0  0  0" xyz="0 0 0"/>
      <inertia ixx="0.000" ixy="0" ixz="0" iyy="0.000" iyz="0" izz="0.000"/>
    </inertial>
    <collision>
      <origin rpy="5.23598775598 0 3.14159265359" xyz="0 0 0"/>
      <geometry>
        <mesh filename="package://strirus_robot_description/meshes/stl/leg_30_degree_normal.stl" scale="1.0 1.0 1.0"/>
      </geometry>
      <gazebo>
        <surface>
          <friction>
            <ode>
              <mu>0.2000</mu>
              <mu2>0.2000</mu2>
              <fdir1>0.000000 0.000000 0.000000</fdir1>
              <slip1>0.000000</slip1>
              <slip2>0.000000</slip2>
            </ode>
          </friction>
          <bounce>
            <restitution_coefficient>0.000000</restitution_coefficient>
            <threshold>100000.000000</threshold>
          </bounce>
          <contact>
            <ode>
              <soft_cfm>0.000000</soft_cfm>
              <soft_erp>0.200000</soft_erp>
              <kp>100000.000000</kp>
              <kd>1.000000</kd>
              <max_vel>100.000000</max_vel>
              <min_depth>0.001000</min_depth>
            </ode>
          </contact>
        </surface>
      </gazebo>
    </collision>
    <visual>
      <origin rpy="5.23598775598 0 3.14159265359" xyz="0 0 0"/>
      <geometry>
        <mesh filename="package://strirus_robot_description/meshes/stl/leg_30_degree_normal.stl" scale="1.0 1.0 1.0"/>
      </geometry>
      <material name="blue"/>
    </visual>
  </link>
  <!-- /////////////// -->
  <joint name="leg_right_1_revolute_joint" type="revolute">
    <parent link="body"/>
    <child link="leg_right_1"/>
    <origin rpy="0       0      0" xyz="-0.25 0.806410161514  0.5"/>
    <axis xyz="1 0  0"/>
    <limit effort="30" lower="-1e+100" upper="1e+100" velocity="10"/>
    <joint_properties damping="0.0" friction="0.0"/>
  </joint>
  <!-- /////////////// -->
  <transmission name="leg_right_1_transmission">
    <type>transmission_interface/SimpleTransmission</type>
    <joint name="leg_right_1_revolute_joint">
      <hardwareInterface>VelocityJointInterface</hardwareInterface>
    </joint>
    <actuator name="leg_right_0_actuator">
      <hardwareInterface>VelocityJointInterface</hardwareInterface>
      <mechanicalReduction>1</mechanicalReduction>
    </actuator>
  </transmission>
  <link name="leg_right_0">
    <inertial>
      <mass value="0.05"/>
      <origin rpy="0  0  0" xyz="0 0 0"/>
      <inertia ixx="0.000" ixy="0" ixz="0" iyy="0.000" iyz="0" izz="0.000"/>
    </inertial>
    <collision>
      <origin rpy="0.0 0 3.14159265359" xyz="0 0 0"/>
      <geometry>
        <mesh filename="package://strirus_robot_description/meshes/stl/leg_30_degree_normal.stl" scale="1.0 1.0 1.0"/>
      </geometry>
      <gazebo>
        <surface>
          <friction>
            <ode>
              <mu>0.2000</mu>
              <mu2>0.2000</mu2>
              <fdir1>0.000000 0.000000 0.000000</fdir1>
              <slip1>0.000000</slip1>
              <slip2>0.000000</slip2>
            </ode>
          </friction>
          <bounce>
            <restitution_coefficient>0.000000</restitution_coefficient>
            <threshold>100000.000000</threshold>
          </bounce>
          <contact>
            <ode>
              <soft_cfm>0.000000</soft_cfm>
              <soft_erp>0.200000</soft_erp>
              <kp>100000.000000</kp>
              <kd>1.000000</kd>
              <max_vel>100.000000</max_vel>
              <min_depth>0.001000</min_depth>
            </ode>
          </contact>
        </surface>
      </gazebo>
    </collision>
    <visual>
      <origin rpy="0.0 0 3.14159265359" xyz="0 0 0"/>
      <geometry>
        <mesh filename="package://strirus_robot_description/meshes/stl/leg_30_degree_normal.stl" scale="1.0 1.0 1.0"/>
      </geometry>
      <material name="blue"/>
    </visual>
  </link>
  <!-- /////////////// -->
  <joint name="leg_right_0_revolute_joint" type="revolute">
    <parent link="body"/>
    <child link="leg_right_0"/>
    <origin rpy="0       0      0" xyz="-0.25 0.25  0.5"/>
    <axis xyz="1 0  0"/>
    <limit effort="30" lower="-1e+100" upper="1e+100" velocity="10"/>
    <joint_properties damping="0.0" friction="0.0"/>
  </joint>
  <!-- /////////////// -->
  <transmission name="leg_right_0_transmission">
    <type>transmission_interface/SimpleTransmission</type>
    <joint name="leg_right_0_revolute_joint">
      <hardwareInterface>VelocityJointInterface</hardwareInterface>
    </joint>
    <actuator name="leg_right_0_actuator">
      <hardwareInterface>VelocityJointInterface</hardwareInterface>
      <mechanicalReduction>1</mechanicalReduction>
    </actuator>
  </transmission>
  <gazebo>
    <joint name="legs_left_1_0_gearbox_joint" type="gearbox">
      <parent>leg_left_0</parent>
      <child>leg_left_1</child>
      <gearbox_ratio>-1</gearbox_ratio>
      <gearbox_reference_body>base_link</gearbox_reference_body>
      <axis>
        <xyz>1.000000 0.000000 0.000000</xyz>
        <use_parent_model_frame>true</use_parent_model_frame>
      </axis>
      <axis2>
        <xyz>1.000000 0.000000 0.000000</xyz>
        <use_parent_model_frame>true</use_parent_model_frame>
      </axis2>
    </joint>
    <joint name="legs_right_1_0_gearbox_joint" type="gearbox">
      <parent>leg_right_0</parent>
      <child>leg_right_1</child>
      <gearbox_ratio>-1</gearbox_ratio>
      <gearbox_reference_body>base_link</gearbox_reference_body>
      <axis>
        <xyz>1.000000 0.000000 0.000000</xyz>
        <use_parent_model_frame>true</use_parent_model_frame>
      </axis>
      <axis2>
        <xyz>1.000000 0.000000 0.000000</xyz>
        <use_parent_model_frame>true</use_parent_model_frame>
      </axis2>
    </joint>
  </gazebo>
</robot>
